<mujoco>
    <worldbody>
        <light diffuse="1 1 1" pos="0 0 10" dir="0 0 -1"/>

        <!-- Ground plane with a neutral color -->
        <geom type="plane" size="10 10 0.05" rgba="0.95 0.95 0.95 1"/> 

        <!-- Door frame as a static object -->
        
        <!-- Left frame -->
        <geom type="box" size="0.1 0.05 2" rgba="0.5 0.5 0.5 1" pos="0 -1 2"/> 
        <!-- Right frame -->
        <geom type="box" size="0.1 0.05 2" rgba="0.5 0.5 0.5 1" pos="0 1 2"/>
        <!-- Top frame -->
        <geom type="box" size="0.1 1.05 0.05" rgba="0.5 0.5 0.5 1" pos="0 0 4.025"/>
        <body>
            <!-- door defined with a hinge joint -->
            <body name="door_body" pos="0 0 2">
                <joint name="door_hinge" type="hinge" pos="0 -0.95 0" axis="0 0 1" range="-90 90"/>
                <geom type="box" size="0.05 0.95 2" rgba="1 1 1 1"/>

                <!-- Door Handle Middle part-->
                <geom type="box" size="0.1 0.025 0.025" rgba="0.5 0.5 0.5 1" pos="0.075 0.75 0"/>
                <!-- Door Handle -->
                <!-- <geom type="box" size="0.025 0.2 0.025" rgba="0.5 0.5 0.5 1" pos="0.15 0.65 0"/> -->
                <body name="door_handle" pos="0 0 0">
                    <joint name="handle_hinge" type="hinge" pos="0 0.75 0" axis="1 0 0" range="0 60" limited="true"/>
                    <geom type="box" size="0.025 0.2 0.025" rgba="0.5 0.5 0.5 1" pos="0.15 0.65 0"/>
                </body>
            </body>
            
        </body>
        
    </worldbody>

    <actuator>
        <motor name="door_hinge" gear="10000000" joint="door_hinge"/>
        <motor name="handle_hinge" gear="1000000" joint="handle_hinge"/>

    </actuator>

    
</mujoco>
